src/simex/meOutput.txt
Received new order: BTC	Bid:true	50010.0	10.0	1
Received new order: BTC	Bid:true	50010.0	5.0	2
Received new order: BTC	Bid:true	50010.0	10.0	3
Received new order: BTC	Bid:true	50009.0	3.0	4
Received new order: BTC	Bid:true	50009.0	5.0	5
Received new order: BTC	Bid:true	50008.0	10.0	6
Matched 10.0 @ 50010.0
Matched 5.0 @ 50010.0
Matched 10.0 @ 50010.0
Matched 3.0 @ 50009.0
Matched 2.0 @ 50009.0
Modified Order: BTC	Bid:true	50009.0	3.0	5
Received new order: BTC	Bid:false	54877.41	3.5464985887088893	100
Received new order: BTC	Bid:false	55187.13	3.547424104398119	200
Matched 1.6096876202630017 @ 54877.41
Modified Order: BTC	Bid:false	54877.41	1.9368109684458876	100
Received new order: BTC	Bid:false	54606.32	2.5667305807397516	400
Matched 1.4476446606505742 @ 54606.32
Modified Order: BTC	Bid:false	54606.32	1.1190859200891774	400
Received new order: BTC	Bid:false	54086.58	1.2029494278422885	600
Received new order: BTC	Bid:false	55522.26	2.6424590694895334	700
Matched 1.2029494278422885 @ 54086.58
Matched 0.3549789616777086 @ 54606.32
Modified Order: BTC	Bid:false	54606.32	0.7641069584114688	400
Matched 0.7641069584114688 @ 54606.32
Matched 1.9368109684458876 @ 54877.41
Received new order: BTC	Bid:true	54989.58	0.8253461364847361	900
Matched 1.3896384832386053 @ 55187.13
Modified Order: BTC	Bid:false	55187.13	2.1577856211595137	200
Matched 2.1577856211595137 @ 55187.13
Received new order: BTC	Bid:true	55434.25	0.6827639709803384	1100
Matched 2.6424590694895334 @ 55522.26
Received new order: BTC	Bid:true	54969.09	2.501592736563423	1300
Received new order: BTC	Bid:true	55472.46	1.4563669777138073	1400
Received new order: BTC	Bid:true	55330.54	0.5165634187933499	1500
Received new order: BTC	Bid:true	55714.8	3.0262488568860877	1600
Matched 1.8541424889325253 @ 55714.8
Modified Order: BTC	Bid:true	55714.8	1.1721063679535624	1600
Matched 1.1721063679535624 @ 55714.8
Matched 0.21630655946741628 @ 55472.46
Modified Order: BTC	Bid:true	55472.46	1.240060418246391	1400
Matched 0.31147559262894964 @ 55472.46
Modified Order: BTC	Bid:true	55472.46	0.9285848256174414	1400
Received new order: BTC	Bid:true	55636.77	2.543660671169106	2000
Matched 2.543660671169106 @ 55636.77
Matched 0.19171177465791622 @ 55472.46
Modified Order: BTC	Bid:true	55472.46	0.7368730509595252	1400
Received new order: BTC	Bid:true	55181.94	2.4001870649294483	2200
Matched 0.7368730509595252 @ 55472.46
Matched 0.6827639709803384 @ 55434.25
Matched 0.5165634187933499 @ 55330.54
Matched 1.2428728283032235 @ 55181.94
Modified Order: BTC	Bid:true	55181.94	1.1573142366262248	2200
Received new order: BTC	Bid:true	55470.94	0.6755181453428583	2400
Received new order: BTC	Bid:true	55528.67	2.3552745494045855	2500
Matched 2.3552745494045855 @ 55528.67
Matched 0.04231106707692556 @ 55470.94
Modified Order: BTC	Bid:true	55470.94	0.6332070782659327	2400
Matched 0.6332070782659327 @ 55470.94
Matched 1.1573142366262248 @ 55181.94
Received new order: BTC	Bid:false	55113.94	1.157582615180371	2700
Received new order: BTC	Bid:true	54573.17	0.7745028145310724	2800
Matched 1.157582615180371 @ 55113.94
Matched 0.8253461364847361 @ 54989.58
Matched 0.9727998354472249 @ 54969.09
Modified Order: BTC	Bid:true	54969.09	1.5287929011161983	1300
Received new order: BTC	Bid:true	55797.59	0.9301824704283745	3100
Received new order: BTC	Bid:true	55516.16	3.416721479112957	3200
Matched 0.9301824704283745 @ 55797.59
Matched 1.5252424431782157 @ 55516.16
Modified Order: BTC	Bid:true	55516.16	1.8914790359347415	3200
Matched 1.5374808059817129 @ 55516.16
Modified Order: BTC	Bid:true	55516.16	0.35399822995302865	3200
Received new order: BTC	Bid:true	54984.96	3.079404803892647	3500
Matched 0.35399822995302865 @ 55516.16
Received new order: BTC	Bid:false	55119.99	1.349461254137473	3600
Matched 1.5185652822788214 @ 54984.96
Modified Order: BTC	Bid:true	54984.96	1.5608395216138256	3500
Matched 1.349461254137473 @ 55119.99
Matched 1.5608395216138256 @ 54984.96
Matched 0.7013425228261871 @ 54969.09
Modified Order: BTC	Bid:true	54969.09	0.8274503782900111	1300
Received new order: BTC	Bid:false	55053.42	2.428369637247012	4000
Matched 0.8274503782900111 @ 54969.09
Received new order: BTC	Bid:false	54922.21	1.6866620022280445	4100
Received new order: BTC	Bid:false	54874.94	2.4321975901285904	4200
Received new order: BTC	Bid:true	54694.0	1.8344004171411652	4300
Received new order: BTC	Bid:true	54232.23	0.8671656214710703	4400
Received new order: BTC	Bid:true	54541.3	2.138275071629424	4500
Received new order: BTC	Bid:true	54217.12	2.2367342759457287	4600
Matched 1.235392774663861 @ 54694.0
Modified Order: BTC	Bid:true	54694.0	0.5990076424773041	4300
Received new order: BTC	Bid:false	55075.11	4.010797569904131	4800
Matched 1.3052063331149923 @ 54874.94
Modified Order: BTC	Bid:false	54874.94	1.126991257013598	4200
Received new order: BTC	Bid:false	54807.03	0.6446059802981052	5000
Received new order: BTC	Bid:true	54518.09	2.0899580642378326	5100
Received new order: BTC	Bid:false	55419.13	1.8183898131529044	5200
Received new order: BTC	Bid:true	54362.31	0.6474755426196013	5300
Received new order: BTC	Bid:true	53839.7	1.8870216347365873	5400
Received new order: BTC	Bid:true	54672.91	2.860773032530859	5500
Received new order: BTC	Bid:false	55616.61	1.3523397042957077	5600
Matched 0.6446059802981052 @ 54807.03
Matched 1.126991257013598 @ 54874.94
Matched 1.0047491558293944 @ 54922.21
Modified Order: BTC	Bid:false	54922.21	0.6819128463986501	4100
Received new order: BTC	Bid:false	54999.75	2.127309255443699	5800
Received new order: BTC	Bid:false	55107.09	3.3965179101820073	5900
Matched 0.5772419663029835 @ 54694.0
Modified Order: BTC	Bid:true	54694.0	0.02176567617432057	4300
Received new order: BTC	Bid:false	55527.12	0.8707017761451841	6100
Received new order: BTC	Bid:false	55791.78	0.6118339561423702	6200
Received new order: BTC	Bid:false	55123.79	1.548352895174186	6300
Received new order: BTC	Bid:true	53924.76	1.7445436429773344	6400
Received new order: BTC	Bid:false	55599.34	1.9705614118959254	6500
Received new order: BTC	Bid:true	54466.89	2.2680282251925883	6600
Matched 0.02176567617432057 @ 54694.0
Matched 1.3198395991556513 @ 54672.91
Modified Order: BTC	Bid:true	54672.91	1.5409334333752076	5500
Matched 0.624185023971034 @ 54672.91
Modified Order: BTC	Bid:true	54672.91	0.9167484094041736	5500
Matched 0.6819128463986501 @ 54922.21
Matched 2.127309255443699 @ 54999.75
Matched 1.0034140811637426 @ 55053.42
Modified Order: BTC	Bid:false	55053.42	1.4249555560832694	4000
Matched 1.1598517318120405 @ 55053.42
Modified Order: BTC	Bid:false	55053.42	0.2651038242712289	4000
Received new order: BTC	Bid:false	56043.62	0.02271295787320704	7100
Matched 0.2651038242712289 @ 55053.42
Received new order: BTC	Bid:true	55056.16	0.37626168238385604	7200
Matched 2.548680372238074 @ 55075.11
Modified Order: BTC	Bid:false	55075.11	1.462117197666057	4800
Matched 1.3008980279401454 @ 55075.11
Modified Order: BTC	Bid:false	55075.11	0.16121916972591155	4800
Received new order: BTC	Bid:false	55916.1	1.5308401363563264	7500
Received new order: BTC	Bid:true	54738.38	2.152004464334525	7600
Matched 0.37626168238385604 @ 55056.16
Received new order: BTC	Bid:false	54880.72	1.2872038983815957	7700
Matched 0.3081788240515233 @ 54738.38
Modified Order: BTC	Bid:true	54738.38	1.8438256402830016	7600
Matched 1.1638256534711646 @ 54880.72
Modified Order: BTC	Bid:false	54880.72	0.12337824491043103	7700
Received new order: BTC	Bid:false	54871.23	1.6199024303749805	8000
Matched 0.25330221745241777 @ 54738.38
Modified Order: BTC	Bid:true	54738.38	1.5905234228305838	7600
Matched 0.5009931220474948 @ 54738.38
Modified Order: BTC	Bid:true	54738.38	1.089530300783089	7600
Matched 1.089530300783089 @ 54738.38
Matched 0.09600615043386451 @ 54672.91
Modified Order: BTC	Bid:true	54672.91	0.8207422589703091	5500
Matched 0.31683468874464227 @ 54871.23
Modified Order: BTC	Bid:false	54871.23	1.3030677416303382	8000
Received new order: BTC	Bid:false	54857.8	2.9006633156752546	8500
Matched 0.8207422589703091 @ 54672.91
